<?xml version="1.0" ?>
<!-- =================================================================================== -->
<!-- |    This document was autogenerated by xacro from lunabot.xacro                  | -->
<!-- |    EDITING THIS FILE BY HAND IS NOT RECOMMENDED                                 | -->
<!-- =================================================================================== -->
<robot name="tracked">
  <!-- Base Footprint -->
  <link name="base_footprint">
    <origin rpy="0 0 0" xyz="0 0 0"/>
  </link>
  <!-- Robot Base -->
  <link name="base_link">
    <visual>
      <origin rpy="0 0 0" xyz="0 0 0"/>
      <geometry>
        <box size="0.5 0.25 0.25"/>
      </geometry>
      <material name="Cyan">
        <color rgba="0 1.0 1.0 1.0"/>
      </material>
    </visual>
    <collision>
      <origin rpy="0 0 0" xyz="0 0 0"/>
      <geometry>
        <box size="0.5 0.25 0.25"/>
      </geometry>
    </collision>
    <inertial>
      <origin rpy="0 0 0" xyz="0 0 0"/>
      <mass value="5"/>
      <inertia ixx="0.052083333333333336" ixy="0.0" ixz="0.0" iyy="0.13020833333333334" iyz="0.0" izz="0.13020833333333334"/>
    </inertial>
  </link>
  <joint name="base_j" type="fixed">
    <parent link="base_footprint"/>
    <child link="base_link"/>
    <origin rpy="0 0 0" xyz="0 0 0.18"/>
  </joint>
  <link name="wheel_f_r_link">
    <visual>
      <origin rpy="1.5707963267948966 0 0" xyz="0 0 0"/>
      <geometry>
        <cylinder length="0.05" radius="0.05"/>
      </geometry>
      <material name="Gray">
        <color rgba="0.5 0.5 0.5 1.0"/>
      </material>
    </visual>
    <collision>
      <origin rpy="1.5707963267948966 0 0" xyz="0 0 0"/>
      <geometry>
        <cylinder length="0.05" radius="0.05"/>
      </geometry>
    </collision>
    <inertial>
      <origin rpy="1.5707963267948966 0 0" xyz="0 0 0"/>
      <mass value="1"/>
      <inertia ixx="0.0008333333333333335" ixy="0" ixz="0" iyy="0.0008333333333333335" iyz="0" izz="0.0012500000000000002"/>
    </inertial>
  </link>
  <joint name="wheel_f_r_j" type="continuous">
    <parent link="base_link"/>
    <child link="wheel_f_r_link"/>
    <origin rpy="0 0 0" xyz="0.17 -0.15 -0.13"/>
    <axis xyz="0 1 0"/>
  </joint>
  <link name="wheel_f_l_link">
    <visual>
      <origin rpy="1.5707963267948966 0 0" xyz="0 0 0"/>
      <geometry>
        <cylinder length="0.05" radius="0.05"/>
      </geometry>
      <material name="Gray">
        <color rgba="0.5 0.5 0.5 1.0"/>
      </material>
    </visual>
    <collision>
      <origin rpy="1.5707963267948966 0 0" xyz="0 0 0"/>
      <geometry>
        <cylinder length="0.05" radius="0.05"/>
      </geometry>
    </collision>
    <inertial>
      <origin rpy="1.5707963267948966 0 0" xyz="0 0 0"/>
      <mass value="1"/>
      <inertia ixx="0.0008333333333333335" ixy="0" ixz="0" iyy="0.0008333333333333335" iyz="0" izz="0.0012500000000000002"/>
    </inertial>
  </link>
  <joint name="wheel_f_l_j" type="continuous">
    <parent link="base_link"/>
    <child link="wheel_f_l_link"/>
    <origin rpy="0 0 0" xyz="0.17 0.15 -0.13"/>
    <axis xyz="0 1 0"/>
  </joint>
  <link name="wheel_b_r_link">
    <visual>
      <origin rpy="1.5707963267948966 0 0" xyz="0 0 0"/>
      <geometry>
        <cylinder length="0.05" radius="0.05"/>
      </geometry>
      <material name="Gray">
        <color rgba="0.5 0.5 0.5 1.0"/>
      </material>
    </visual>
    <collision>
      <origin rpy="1.5707963267948966 0 0" xyz="0 0 0"/>
      <geometry>
        <cylinder length="0.05" radius="0.05"/>
      </geometry>
    </collision>
    <inertial>
      <origin rpy="1.5707963267948966 0 0" xyz="0 0 0"/>
      <mass value="1"/>
      <inertia ixx="0.0008333333333333335" ixy="0" ixz="0" iyy="0.0008333333333333335" iyz="0" izz="0.0012500000000000002"/>
    </inertial>
  </link>
  <joint name="wheel_b_r_j" type="continuous">
    <parent link="base_link"/>
    <child link="wheel_b_r_link"/>
    <origin rpy="0 0 0" xyz="-0.17 -0.15 -0.13"/>
    <axis xyz="0 1 0"/>
  </joint>
  <link name="wheel_b_l_link">
    <visual>
      <origin rpy="1.5707963267948966 0 0" xyz="0 0 0"/>
      <geometry>
        <cylinder length="0.05" radius="0.05"/>
      </geometry>
      <material name="Gray">
        <color rgba="0.5 0.5 0.5 1.0"/>
      </material>
    </visual>
    <collision>
      <origin rpy="1.5707963267948966 0 0" xyz="0 0 0"/>
      <geometry>
        <cylinder length="0.05" radius="0.05"/>
      </geometry>
    </collision>
    <inertial>
      <origin rpy="1.5707963267948966 0 0" xyz="0 0 0"/>
      <mass value="1"/>
      <inertia ixx="0.0008333333333333335" ixy="0" ixz="0" iyy="0.0008333333333333335" iyz="0" izz="0.0012500000000000002"/>
    </inertial>
  </link>
  <joint name="wheel_b_l_j" type="continuous">
    <parent link="base_link"/>
    <child link="wheel_b_l_link"/>
    <origin rpy="0 0 0" xyz="-0.17 0.15 -0.13"/>
    <axis xyz="0 1 0"/>
  </joint>
  <link name="depth_camera_link">
    <origin rpy="0 0 0" xyz="0 0 0"/>
    <visual>
      <geometry>
        <box size="0.05 0.05 0.05"/>
      </geometry>
      <collision>
        <box size="0.05 0.05 0.05"/>
      </collision>
      <inertial>
        <origin rpy="0 0 0" xyz="0 0 0"/>
        <mass value="0.1"/>
        <inertia ixx="4.166666666666667e-05" ixy="0.0" ixz="0.0" iyy="4.166666666666667e-05" iyz="0.0" izz="4.166666666666667e-05"/>
      </inertial>
    </visual>
  </link>
  <joint name="depth_camera_j" type="fixed">
    <parent link="base_link"/>
    <child link="depth_camera_link"/>
    <origin rpy="0 0 0" xyz="0.25 0 0.125"/>
  </joint>
  <link name="depth_camera_optical_link"/>
  <joint name="depth_camera_optical_j" type="fixed">
    <parent link="depth_camera_link"/>
    <child link="depth_camera_optical_link"/>
    <origin rpy="-1.5707963267948966 0 -1.5707963267948966" xyz="0 0 0"/>
  </joint>
  <link name="camera_link">
    <origin rpy="0 0 0" xyz="0 0 0"/>
    <visual>
      <geometry>
        <box size="0.05 0.05 0.05"/>
      </geometry>
      <collision>
        <box size="0.05 0.05 0.05"/>
      </collision>
    </visual>
  </link>
  <joint name="camera_j" type="fixed">
    <parent link="base_link"/>
    <child link="camera_link"/>
    <origin rpy="0 0 3.141592653589793" xyz="-0.25 0 0.125"/>
  </joint>
  <link name="camera_optical_link"/>
  <joint name="camera_optical_j" type="fixed">
    <parent link="camera_link"/>
    <child link="camera_optical_link"/>
    <origin rpy="-1.5707963267948966 0 -1.5707963267948966" xyz="0 0 0"/>
  </joint>
  <gazebo>
    <plugin filename="libgazebo_ros_diff_drive.so" name="diff_drive_f">
      <update_rate>30</update_rate>
      <left_joint>wheel_f_l_j</left_joint>
      <right_joint>wheel_f_r_j</right_joint>
      <wheel_separation>0.3</wheel_separation>
      <wheel_diameter>0.1</wheel_diameter>
      <max_wheel_torque>20</max_wheel_torque>
      <max_wheel_acceleration>1.0</max_wheel_acceleration>
      <command_topic>cmd_vel</command_topic>
      <publish_odom>false</publish_odom>
      <publish_odom_tf>false</publish_odom_tf>
      <publish_wheel_tf>true</publish_wheel_tf>
      <odometry_frame>odom</odometry_frame>
      <robot_base_frame>base_link</robot_base_frame>
    </plugin>
    <!-- <plugin name='diff_drive_m' filename='libgazebo_ros_diff_drive.so'>
            <update_rate>30</update_rate>
            <left_joint>wheel_m_l_j</left_joint>
            <right_joint>wheel_m_r_j</right_joint>
            <wheel_separation>0.3</wheel_separation>
            <wheel_diameter>0.1</wheel_diameter>
            <max_wheel_torque>20</max_wheel_torque>
            <max_wheel_acceleration>1.0</max_wheel_acceleration>
            <command_topic>cmd_vel</command_topic>
            <publish_odom>false</publish_odom>
            <publish_odom_tf>false</publish_odom_tf>
            <publish_wheel_tf>true</publish_wheel_tf>

            <odometry_frame>odom</odometry_frame>
            <robot_base_frame>base_link</robot_base_frame>
        </plugin> -->
    <plugin filename="libgazebo_ros_diff_drive.so" name="diff_drive_b">
      <update_rate>30</update_rate>
      <left_joint>wheel_b_l_j</left_joint>
      <right_joint>wheel_b_r_j</right_joint>
      <wheel_separation>0.3</wheel_separation>
      <wheel_diameter>0.1</wheel_diameter>
      <max_wheel_torque>20</max_wheel_torque>
      <max_wheel_acceleration>1.0</max_wheel_acceleration>
      <command_topic>cmd_vel</command_topic>
      <publish_odom>false</publish_odom>
      <publish_odom_tf>false</publish_odom_tf>
      <publish_wheel_tf>true</publish_wheel_tf>
      <odometry_frame>odom</odometry_frame>
      <robot_base_frame>base_link</robot_base_frame>
    </plugin>
  </gazebo>
  <gazebo reference="depth_camera_link">
    <material>Gazebo/Red</material>
    <sensor name="depth_camera" type="depth">
      <always_on>1</always_on>
      <update_rate>10</update_rate>
      <visualize>true</visualize>
      <camera>
        <horizontal_fov>1.51844</horizontal_fov>
        <image>
          <width>320</width>
          <height>320</height>
          <format>R8G8B8</format>
        </image>
        <clip>
          <near>0.05</near>
          <far>10.0</far>
        </clip>
      </camera>
      <plugin filename="libgazebo_ros_camera.so" name="depth_camera_controller">
        <frame_name>depth_camera_optical_link</frame_name>
      </plugin>
    </sensor>
  </gazebo>
  <gazebo reference="camera_link">
    <material>Gazebo/Red</material>
    <sensor name="camera" type="camera">
      <always_on>1</always_on>
      <update_rate>10</update_rate>
      <visualize>true</visualize>
      <camera>
        <horizontal_fov>1.089</horizontal_fov>
        <image>
          <width>320</width>
          <height>320</height>
          <format>R8G8B8</format>
        </image>
        <clip>
          <near>0.05</near>
          <far>10.0</far>
        </clip>
      </camera>
      <plugin filename="libgazebo_ros_camera.so" name="camera_controller">
        <frame_name>camera_optical_link</frame_name>
      </plugin>
    </sensor>
  </gazebo>
</robot>
